<?xml version="1.0"?>

<robot name="line_robot">

  <!-- ================= BASE LINK ================= -->

  <link name="base_link">

    <visual>
      <geometry>
        <box size="0.20 0.15 0.05"/>
      </geometry>

      <material name="Blue">
        <color rgba="0.1 0.1 0.8 1"/>
      </material>
    </visual>

    <collision>
      <geometry>
        <box size="0.20 0.15 0.05"/>
      </geometry>
    </collision>

    <inertial>
      <mass value="1.0"/>

      <origin xyz="0 0 0"/>

      <inertia
        ixx="0.01"
        ixy="0.0"
        ixz="0.0"
        iyy="0.01"
        iyz="0.0"
        izz="0.01"/>
    </inertial>

  </link>

  <!-- ================= LEFT WHEEL ================= -->

  <link name="left_wheel">

    <visual>
      <geometry>
        <cylinder radius="0.03" length="0.02"/>
      </geometry>

      <material name="Black">
        <color rgba="0 0 0 1"/>
      </material>
    </visual>

    <collision>
      <geometry>
        <cylinder radius="0.03" length="0.02"/>
      </geometry>
    </collision>

  </link>

  <!-- ================= RIGHT WHEEL ================= -->

  <link name="right_wheel">

    <visual>
      <geometry>
        <cylinder radius="0.03" length="0.02"/>
      </geometry>

      <material name="Black">
        <color rgba="0 0 0 1"/>
      </material>
    </visual>

    <collision>
      <geometry>
        <cylinder radius="0.03" length="0.02"/>
      </geometry>
    </collision>

  </link>

  <!-- ================= CAMERA LINK ================= -->

  <link name="camera_link">

    <visual>
      <geometry>
        <box size="0.03 0.03 0.03"/>
      </geometry>

      <material name="Red">
        <color rgba="1 0 0 1"/>
      </material>
    </visual>

  </link>

  <!-- ================= JOINTS ================= -->

  <joint name="left_wheel_joint" type="continuous">

    <parent link="base_link"/>
    <child link="left_wheel"/>

    <origin xyz="0 0.08 -0.03" rpy="1.5707 0 0"/>

    <axis xyz="0 0 1"/>

  </joint>

  <joint name="right_wheel_joint" type="continuous">

    <parent link="base_link"/>
    <child link="right_wheel"/>

    <origin xyz="0 -0.08 -0.03" rpy="1.5707 0 0"/>

    <axis xyz="0 0 1"/>

  </joint>

  <!-- CAMERA JOINT -->

  <joint name="camera_joint" type="fixed">

    <parent link="base_link"/>
    <child link="camera_link"/>

    <origin xyz="0.08 0 -0.01" rpy="0 1.57 0"/>

  </joint>

  <!-- ================= GAZEBO COLORS ================= -->

  <gazebo reference="base_link">
    <material>Gazebo/Blue</material>
  </gazebo>

  <gazebo reference="left_wheel">
    <material>Gazebo/Black</material>
  </gazebo>

  <gazebo reference="right_wheel">
    <material>Gazebo/Black</material>
  </gazebo>

  <!-- ================= CAMERA SENSOR ================= -->

  <gazebo reference="camera_link">

    <sensor name="line_camera" type="camera">

      <always_on>true</always_on>

      <update_rate>30</update_rate>

      <visualize>true</visualize>

      <camera>

        <horizontal_fov>1.0</horizontal_fov>

        <image>
          <width>640</width>
          <height>480</height>
          <format>R8G8B8</format>
        </image>

        <clip>
          <near>0.01</near>
          <far>10</far>
        </clip>

      </camera>

      <plugin name="camera_plugin" filename="libgazebo_ros_camera.so">

        <ros>
          <namespace>/camera</namespace>
        </ros>

        <camera_name>line_camera</camera_name>

        <image_topic_name>image_raw</image_topic_name>

      </plugin>

    </sensor>

  </gazebo>

  <!-- ================= DIFF DRIVE ================= -->

  <gazebo>

    <plugin name="diff_drive" filename="libgazebo_ros_diff_drive.so">

      <left_joint>left_wheel_joint</left_joint>
      <right_joint>right_wheel_joint</right_joint>

      <wheel_separation>0.16</wheel_separation>
      <wheel_diameter>0.06</wheel_diameter>

      <max_wheel_torque>5</max_wheel_torque>
      <max_wheel_acceleration>1.0</max_wheel_acceleration>
      
      <topicName>/cmd_vel</topicName>

      <odometry_topic>/odom</odometry_topic>

      <robot_base_frame>base_link</robot_base_frame>

      <publish_odom>true</publish_odom>

    </plugin>

</gazebo>

</robot>
